{"config_path": "config/config.yaml", "timestamp": "2025-08-28T06:15:07.917670Z", "level": "info", "event": "Config loaded successfully"}
{"timestamp": "2025-08-28T06:15:07.918403Z", "level": "error", "event": "Error in [/Users/anujpandey/llm_projects/end_to_end_projects/adek_ai_v2/src/data_retrieval/retrieval.py] at line [392]\nMessage: Conversational RAG test failed: Error in [/Users/anujpandey/llm_projects/end_to_end_projects/adek_ai_v2/src/data_retrieval/retrieval.py] at line [154]\nMessage: Failed to initialize ConversationalRAG: 'model'\nTraceback:\nTraceback (most recent call last):\n  File \"/Users/anujpandey/llm_projects/end_to_end_projects/adek_ai_v2/src/data_retrieval/retrieval.py\", line 154, in __init__\n    model_name = config[\"model\"][\"openai\"][\"model_name\"]\n                 ~~~~~~^^^^^^^^^\nKeyError: 'model'\n\nTraceback:\nTraceback (most recent call last):\n  File \"/Users/anujpandey/llm_projects/end_to_end_projects/adek_ai_v2/src/data_retrieval/retrieval.py\", line 154, in __init__\n    model_name = config[\"model\"][\"openai\"][\"model_name\"]\n                 ~~~~~~^^^^^^^^^\nKeyError: 'model'\n\nDuring handling of the above exception, another exception occurred:\n\nTraceback (most recent call last):\n  File \"/Users/anujpandey/llm_projects/end_to_end_projects/adek_ai_v2/src/data_retrieval/retrieval.py\", line 392, in test_conversational_rag\n    rag = ConversationalRAG(session_id=\"test_session_1\", config=config)\n          ^^^^^^^^^^^^^^^^^^^^^^^^^^^^^^^^^^^^^^^^^^^^^^^^^^^^^^^^^^^^^\n  File \"/Users/anujpandey/llm_projects/end_to_end_projects/adek_ai_v2/src/data_retrieval/retrieval.py\", line 177, in __init__\n    raise CommonException(f\"Failed to initialize ConversationalRAG: {e}\", sys)\nexception.custom_exception.CommonException: Error in [/Users/anujpandey/llm_projects/end_to_end_projects/adek_ai_v2/src/data_retrieval/retrieval.py] at line [154]\nMessage: Failed to initialize ConversationalRAG: 'model'\nTraceback:\nTraceback (most recent call last):\n  File \"/Users/anujpandey/llm_projects/end_to_end_projects/adek_ai_v2/src/data_retrieval/retrieval.py\", line 154, in __init__\n    model_name = config[\"model\"][\"openai\"][\"model_name\"]\n                 ~~~~~~^^^^^^^^^\nKeyError: 'model'\n\n"}
